2021-12-04 13:43:18,510 - [test_invest.py-->line:43] - ERROR: invest：投资人正常投资【失败】*****
2021-12-04 13:43:18,510 - [test_invest.py-->line:44] - ERROR: 2 != 0
Traceback (most recent call last):
  File "C:\Users\Administrator\Desktop\docjer实战接口自动化\LG_jiekou_unittest\testcase\test_invest.py", line 40, in test_recharge
    self.assertEqual(res.json()['code'],expected['code'])
  File "C:\Users\Administrator\AppData\Local\Programs\Python\Python37\lib\unittest\case.py", line 852, in assertEqual
    assertion_func(first, second, msg=msg)
  File "C:\Users\Administrator\AppData\Local\Programs\Python\Python37\lib\unittest\case.py", line 845, in _baseAssertEqual
    raise self.failureException(msg)
AssertionError: 2 != 0
