ERROR    ligen:test_withdraw.py:67 withdraw：会员id为数值【失败】*****
ERROR    ligen:test_withdraw.py:68 0 != 2
Traceback (most recent call last):
  File "C:\Users\Administrator\Desktop\docjer实战接口自动化\LG_jiekou_unittest\testcase\test_withdraw.py", line 64, in test_withdraw
    self.assertEqual(res.json()['code'],expected['code'])
  File "C:\Users\Administrator\AppData\Local\Programs\Python\Python37\lib\unittest\case.py", line 852, in assertEqual
    assertion_func(first, second, msg=msg)
  File "C:\Users\Administrator\AppData\Local\Programs\Python\Python37\lib\unittest\case.py", line 845, in _baseAssertEqual
    raise self.failureException(msg)
AssertionError: 0 != 2