2021-12-04 13:52:52,569 - [test_withdraw.py-->line:67] - ERROR: withdraw：会员id为数值【失败】*****
2021-12-04 13:52:52,570 - [test_withdraw.py-->line:68] - ERROR: 0 != 2
Traceback (most recent call last):
  File "C:\Users\Administrator\Desktop\docjer实战接口自动化\LG_jiekou_unittest\testcase\test_withdraw.py", line 64, in test_withdraw
    self.assertEqual(res.json()['code'],expected['code'])
  File "C:\Users\Administrator\AppData\Local\Programs\Python\Python37\lib\unittest\case.py", line 852, in assertEqual
    assertion_func(first, second, msg=msg)
  File "C:\Users\Administrator\AppData\Local\Programs\Python\Python37\lib\unittest\case.py", line 845, in _baseAssertEqual
    raise self.failureException(msg)
AssertionError: 0 != 2
